{
  "nbformat": 4,
  "nbformat_minor": 0,
  "metadata": {
    "colab": {
      "provenance": []
    },
    "kernelspec": {
      "name": "python3",
      "display_name": "Python 3"
    },
    "language_info": {
      "name": "python"
    }
  },
  "cells": [
    {
      "cell_type": "markdown",
      "source": [
        "#CNN"
      ],
      "metadata": {
        "id": "CpaNnAy4GMVy"
      }
    },
    {
      "cell_type": "code",
      "source": [
        "import numpy as np\n",
        "from sklearn.model_selection import train_test_split\n",
        "from keras.models import Sequential\n",
        "from keras.layers import Conv2D, MaxPooling2D, Flatten, Dense\n",
        "from keras.preprocessing.image import ImageDataGenerator"
      ],
      "metadata": {
        "id": "x2k-eKPDGOwC"
      },
      "execution_count": 1,
      "outputs": []
    },
    {
      "cell_type": "code",
      "source": [
        "from google.colab import drive\n",
        "drive.mount('/content/drive')"
      ],
      "metadata": {
        "colab": {
          "base_uri": "https://localhost:8080/"
        },
        "id": "AUxECV1YHEYa",
        "outputId": "b629a3e2-be96-4f2b-d8c6-d211984dea44"
      },
      "execution_count": 2,
      "outputs": [
        {
          "output_type": "stream",
          "name": "stdout",
          "text": [
            "Drive already mounted at /content/drive; to attempt to forcibly remount, call drive.mount(\"/content/drive\", force_remount=True).\n"
          ]
        }
      ]
    },
    {
      "cell_type": "code",
      "source": [
        "# นำเข้ารูปภาพจาก Google Drive โดยระบุตำแหน่งของโฟลเดอร์ที่เก็บรูปภาพ\n",
        "image_folder_path = '/content/drive/MyDrive/344-331/mini_project/dataset'"
      ],
      "metadata": {
        "id": "ASGhymPKHF-a"
      },
      "execution_count": 3,
      "outputs": []
    },
    {
      "cell_type": "code",
      "source": [
        "# ทำการแบ่งชุดข้อมูลเป็น train และ test\n",
        "train_datagen = ImageDataGenerator(rescale=1./255, validation_split=0.2)"
      ],
      "metadata": {
        "id": "dC0gqznQHIBU"
      },
      "execution_count": 4,
      "outputs": []
    },
    {
      "cell_type": "code",
      "source": [
        "train_generator = train_datagen.flow_from_directory(\n",
        "    image_folder_path,\n",
        "    target_size=(32, 32),\n",
        "    batch_size=32,\n",
        "    class_mode='categorical',  # กำหนด class_mode เป็น 'categorical'\n",
        "    subset='training')  # ใช้ subset='training' เพื่อให้มันใช้ชุดข้อมูลสำหรับการฝึก\n",
        "\n",
        "validation_generator = train_datagen.flow_from_directory(\n",
        "    image_folder_path,\n",
        "    target_size=(32, 32),\n",
        "    batch_size=32,\n",
        "    class_mode='categorical',  # กำหนด class_mode เป็น 'categorical'\n",
        "    subset='validation')  # ใช้ subset='validation' เพื่อให้มันใช้ชุดข้อมูลสำหรับการทดสอบ\n"
      ],
      "metadata": {
        "colab": {
          "base_uri": "https://localhost:8080/"
        },
        "id": "nkJ3HvF4HRMa",
        "outputId": "f4ce33e8-47f2-490c-c900-bfc06e3adc6a"
      },
      "execution_count": 18,
      "outputs": [
        {
          "output_type": "stream",
          "name": "stdout",
          "text": [
            "Found 3345 images belonging to 11 classes.\n",
            "Found 831 images belonging to 11 classes.\n"
          ]
        }
      ]
    },
    {
      "cell_type": "code",
      "source": [
        "NUM_CLASSES = 10"
      ],
      "metadata": {
        "id": "4AWJ1O2xHzOb"
      },
      "execution_count": 19,
      "outputs": []
    },
    {
      "cell_type": "code",
      "source": [
        "# Define CNN architecture\n",
        "model = Sequential()\n",
        "model.add(Conv2D(32, (3, 3), activation='relu', input_shape=(32, 32, 3)))\n",
        "model.add(MaxPooling2D((2, 2)))\n",
        "model.add(Conv2D(64, (3, 3), activation='relu'))\n",
        "model.add(MaxPooling2D((2, 2)))\n",
        "model.add(Flatten())\n",
        "model.add(Dense(64, activation='relu'))\n",
        "model.add(Dense(NUM_CLASSES, activation='softmax')) # ปรับ NUM_CLASSES ให้เป็นจำนวนคลาสของชุดข้อมูลของคุณ\n",
        "model.compile(optimizer='adam', loss='categorical_crossentropy', metrics=['accuracy'])"
      ],
      "metadata": {
        "id": "Werb5ue6Hc19"
      },
      "execution_count": 20,
      "outputs": []
    },
    {
      "cell_type": "code",
      "source": [
        "# Train the model\n",
        "history = model.fit(\n",
        "    train_generator,\n",
        "    steps_per_epoch=train_generator.samples/train_generator.batch_size,\n",
        "    epochs=5,\n",
        "    validation_data=validation_generator,\n",
        "    validation_steps=validation_generator.samples/validation_generator.batch_size)"
      ],
      "metadata": {
        "colab": {
          "base_uri": "https://localhost:8080/",
          "height": 1000
        },
        "id": "cvOZ3yJAHh2p",
        "outputId": "cb41b0c8-115d-41dd-befc-51c027f6d3e8"
      },
      "execution_count": 25,
      "outputs": [
        {
          "output_type": "stream",
          "name": "stdout",
          "text": [
            "Epoch 1/10\n"
          ]
        },
        {
          "output_type": "error",
          "ename": "InvalidArgumentError",
          "evalue": "Graph execution error:\n\nDetected at node categorical_crossentropy/softmax_cross_entropy_with_logits defined at (most recent call last):\n  File \"/usr/lib/python3.10/runpy.py\", line 196, in _run_module_as_main\n\n  File \"/usr/lib/python3.10/runpy.py\", line 86, in _run_code\n\n  File \"/usr/local/lib/python3.10/dist-packages/colab_kernel_launcher.py\", line 37, in <module>\n\n  File \"/usr/local/lib/python3.10/dist-packages/traitlets/config/application.py\", line 992, in launch_instance\n\n  File \"/usr/local/lib/python3.10/dist-packages/ipykernel/kernelapp.py\", line 619, in start\n\n  File \"/usr/local/lib/python3.10/dist-packages/tornado/platform/asyncio.py\", line 195, in start\n\n  File \"/usr/lib/python3.10/asyncio/base_events.py\", line 603, in run_forever\n\n  File \"/usr/lib/python3.10/asyncio/base_events.py\", line 1909, in _run_once\n\n  File \"/usr/lib/python3.10/asyncio/events.py\", line 80, in _run\n\n  File \"/usr/local/lib/python3.10/dist-packages/tornado/ioloop.py\", line 685, in <lambda>\n\n  File \"/usr/local/lib/python3.10/dist-packages/tornado/ioloop.py\", line 738, in _run_callback\n\n  File \"/usr/local/lib/python3.10/dist-packages/tornado/gen.py\", line 825, in inner\n\n  File \"/usr/local/lib/python3.10/dist-packages/tornado/gen.py\", line 786, in run\n\n  File \"/usr/local/lib/python3.10/dist-packages/ipykernel/kernelbase.py\", line 361, in process_one\n\n  File \"/usr/local/lib/python3.10/dist-packages/tornado/gen.py\", line 234, in wrapper\n\n  File \"/usr/local/lib/python3.10/dist-packages/ipykernel/kernelbase.py\", line 261, in dispatch_shell\n\n  File \"/usr/local/lib/python3.10/dist-packages/tornado/gen.py\", line 234, in wrapper\n\n  File \"/usr/local/lib/python3.10/dist-packages/ipykernel/kernelbase.py\", line 539, in execute_request\n\n  File \"/usr/local/lib/python3.10/dist-packages/tornado/gen.py\", line 234, in wrapper\n\n  File \"/usr/local/lib/python3.10/dist-packages/ipykernel/ipkernel.py\", line 302, in do_execute\n\n  File \"/usr/local/lib/python3.10/dist-packages/ipykernel/zmqshell.py\", line 539, in run_cell\n\n  File \"/usr/local/lib/python3.10/dist-packages/IPython/core/interactiveshell.py\", line 2975, in run_cell\n\n  File \"/usr/local/lib/python3.10/dist-packages/IPython/core/interactiveshell.py\", line 3030, in _run_cell\n\n  File \"/usr/local/lib/python3.10/dist-packages/IPython/core/async_helpers.py\", line 78, in _pseudo_sync_runner\n\n  File \"/usr/local/lib/python3.10/dist-packages/IPython/core/interactiveshell.py\", line 3257, in run_cell_async\n\n  File \"/usr/local/lib/python3.10/dist-packages/IPython/core/interactiveshell.py\", line 3473, in run_ast_nodes\n\n  File \"/usr/local/lib/python3.10/dist-packages/IPython/core/interactiveshell.py\", line 3553, in run_code\n\n  File \"<ipython-input-21-7d1a7289e7ff>\", line 2, in <cell line: 2>\n\n  File \"/usr/local/lib/python3.10/dist-packages/keras/src/utils/traceback_utils.py\", line 65, in error_handler\n\n  File \"/usr/local/lib/python3.10/dist-packages/keras/src/engine/training.py\", line 1807, in fit\n\n  File \"/usr/local/lib/python3.10/dist-packages/keras/src/engine/training.py\", line 1401, in train_function\n\n  File \"/usr/local/lib/python3.10/dist-packages/keras/src/engine/training.py\", line 1384, in step_function\n\n  File \"/usr/local/lib/python3.10/dist-packages/keras/src/engine/training.py\", line 1373, in run_step\n\n  File \"/usr/local/lib/python3.10/dist-packages/keras/src/engine/training.py\", line 1151, in train_step\n\n  File \"/usr/local/lib/python3.10/dist-packages/keras/src/engine/training.py\", line 1209, in compute_loss\n\n  File \"/usr/local/lib/python3.10/dist-packages/keras/src/engine/compile_utils.py\", line 277, in __call__\n\n  File \"/usr/local/lib/python3.10/dist-packages/keras/src/losses.py\", line 143, in __call__\n\n  File \"/usr/local/lib/python3.10/dist-packages/keras/src/losses.py\", line 270, in call\n\n  File \"/usr/local/lib/python3.10/dist-packages/keras/src/losses.py\", line 2221, in categorical_crossentropy\n\n  File \"/usr/local/lib/python3.10/dist-packages/keras/src/backend.py\", line 5579, in categorical_crossentropy\n\nlogits and labels must be broadcastable: logits_size=[32,10] labels_size=[32,11]\n\t [[{{node categorical_crossentropy/softmax_cross_entropy_with_logits}}]] [Op:__inference_train_function_3999]",
          "traceback": [
            "\u001b[0;31m---------------------------------------------------------------------------\u001b[0m",
            "\u001b[0;31mInvalidArgumentError\u001b[0m                      Traceback (most recent call last)",
            "\u001b[0;32m<ipython-input-25-ba94b66fd80d>\u001b[0m in \u001b[0;36m<cell line: 2>\u001b[0;34m()\u001b[0m\n\u001b[1;32m      1\u001b[0m \u001b[0;31m# Train the model\u001b[0m\u001b[0;34m\u001b[0m\u001b[0;34m\u001b[0m\u001b[0m\n\u001b[0;32m----> 2\u001b[0;31m history = model.fit(\n\u001b[0m\u001b[1;32m      3\u001b[0m     \u001b[0mtrain_generator\u001b[0m\u001b[0;34m,\u001b[0m\u001b[0;34m\u001b[0m\u001b[0;34m\u001b[0m\u001b[0m\n\u001b[1;32m      4\u001b[0m     \u001b[0msteps_per_epoch\u001b[0m\u001b[0;34m=\u001b[0m\u001b[0mtrain_generator\u001b[0m\u001b[0;34m.\u001b[0m\u001b[0msamples\u001b[0m\u001b[0;34m/\u001b[0m\u001b[0mtrain_generator\u001b[0m\u001b[0;34m.\u001b[0m\u001b[0mbatch_size\u001b[0m\u001b[0;34m,\u001b[0m\u001b[0;34m\u001b[0m\u001b[0;34m\u001b[0m\u001b[0m\n\u001b[1;32m      5\u001b[0m     \u001b[0mepochs\u001b[0m\u001b[0;34m=\u001b[0m\u001b[0;36m10\u001b[0m\u001b[0;34m,\u001b[0m\u001b[0;34m\u001b[0m\u001b[0;34m\u001b[0m\u001b[0m\n",
            "\u001b[0;32m/usr/local/lib/python3.10/dist-packages/keras/src/utils/traceback_utils.py\u001b[0m in \u001b[0;36merror_handler\u001b[0;34m(*args, **kwargs)\u001b[0m\n\u001b[1;32m     68\u001b[0m             \u001b[0;31m# To get the full stack trace, call:\u001b[0m\u001b[0;34m\u001b[0m\u001b[0;34m\u001b[0m\u001b[0m\n\u001b[1;32m     69\u001b[0m             \u001b[0;31m# `tf.debugging.disable_traceback_filtering()`\u001b[0m\u001b[0;34m\u001b[0m\u001b[0;34m\u001b[0m\u001b[0m\n\u001b[0;32m---> 70\u001b[0;31m             \u001b[0;32mraise\u001b[0m \u001b[0me\u001b[0m\u001b[0;34m.\u001b[0m\u001b[0mwith_traceback\u001b[0m\u001b[0;34m(\u001b[0m\u001b[0mfiltered_tb\u001b[0m\u001b[0;34m)\u001b[0m \u001b[0;32mfrom\u001b[0m \u001b[0;32mNone\u001b[0m\u001b[0;34m\u001b[0m\u001b[0;34m\u001b[0m\u001b[0m\n\u001b[0m\u001b[1;32m     71\u001b[0m         \u001b[0;32mfinally\u001b[0m\u001b[0;34m:\u001b[0m\u001b[0;34m\u001b[0m\u001b[0;34m\u001b[0m\u001b[0m\n\u001b[1;32m     72\u001b[0m             \u001b[0;32mdel\u001b[0m \u001b[0mfiltered_tb\u001b[0m\u001b[0;34m\u001b[0m\u001b[0;34m\u001b[0m\u001b[0m\n",
            "\u001b[0;32m/usr/local/lib/python3.10/dist-packages/tensorflow/python/eager/execute.py\u001b[0m in \u001b[0;36mquick_execute\u001b[0;34m(op_name, num_outputs, inputs, attrs, ctx, name)\u001b[0m\n\u001b[1;32m     51\u001b[0m   \u001b[0;32mtry\u001b[0m\u001b[0;34m:\u001b[0m\u001b[0;34m\u001b[0m\u001b[0;34m\u001b[0m\u001b[0m\n\u001b[1;32m     52\u001b[0m     \u001b[0mctx\u001b[0m\u001b[0;34m.\u001b[0m\u001b[0mensure_initialized\u001b[0m\u001b[0;34m(\u001b[0m\u001b[0;34m)\u001b[0m\u001b[0;34m\u001b[0m\u001b[0;34m\u001b[0m\u001b[0m\n\u001b[0;32m---> 53\u001b[0;31m     tensors = pywrap_tfe.TFE_Py_Execute(ctx._handle, device_name, op_name,\n\u001b[0m\u001b[1;32m     54\u001b[0m                                         inputs, attrs, num_outputs)\n\u001b[1;32m     55\u001b[0m   \u001b[0;32mexcept\u001b[0m \u001b[0mcore\u001b[0m\u001b[0;34m.\u001b[0m\u001b[0m_NotOkStatusException\u001b[0m \u001b[0;32mas\u001b[0m \u001b[0me\u001b[0m\u001b[0;34m:\u001b[0m\u001b[0;34m\u001b[0m\u001b[0;34m\u001b[0m\u001b[0m\n",
            "\u001b[0;31mInvalidArgumentError\u001b[0m: Graph execution error:\n\nDetected at node categorical_crossentropy/softmax_cross_entropy_with_logits defined at (most recent call last):\n  File \"/usr/lib/python3.10/runpy.py\", line 196, in _run_module_as_main\n\n  File \"/usr/lib/python3.10/runpy.py\", line 86, in _run_code\n\n  File \"/usr/local/lib/python3.10/dist-packages/colab_kernel_launcher.py\", line 37, in <module>\n\n  File \"/usr/local/lib/python3.10/dist-packages/traitlets/config/application.py\", line 992, in launch_instance\n\n  File \"/usr/local/lib/python3.10/dist-packages/ipykernel/kernelapp.py\", line 619, in start\n\n  File \"/usr/local/lib/python3.10/dist-packages/tornado/platform/asyncio.py\", line 195, in start\n\n  File \"/usr/lib/python3.10/asyncio/base_events.py\", line 603, in run_forever\n\n  File \"/usr/lib/python3.10/asyncio/base_events.py\", line 1909, in _run_once\n\n  File \"/usr/lib/python3.10/asyncio/events.py\", line 80, in _run\n\n  File \"/usr/local/lib/python3.10/dist-packages/tornado/ioloop.py\", line 685, in <lambda>\n\n  File \"/usr/local/lib/python3.10/dist-packages/tornado/ioloop.py\", line 738, in _run_callback\n\n  File \"/usr/local/lib/python3.10/dist-packages/tornado/gen.py\", line 825, in inner\n\n  File \"/usr/local/lib/python3.10/dist-packages/tornado/gen.py\", line 786, in run\n\n  File \"/usr/local/lib/python3.10/dist-packages/ipykernel/kernelbase.py\", line 361, in process_one\n\n  File \"/usr/local/lib/python3.10/dist-packages/tornado/gen.py\", line 234, in wrapper\n\n  File \"/usr/local/lib/python3.10/dist-packages/ipykernel/kernelbase.py\", line 261, in dispatch_shell\n\n  File \"/usr/local/lib/python3.10/dist-packages/tornado/gen.py\", line 234, in wrapper\n\n  File \"/usr/local/lib/python3.10/dist-packages/ipykernel/kernelbase.py\", line 539, in execute_request\n\n  File \"/usr/local/lib/python3.10/dist-packages/tornado/gen.py\", line 234, in wrapper\n\n  File \"/usr/local/lib/python3.10/dist-packages/ipykernel/ipkernel.py\", line 302, in do_execute\n\n  File \"/usr/local/lib/python3.10/dist-packages/ipykernel/zmqshell.py\", line 539, in run_cell\n\n  File \"/usr/local/lib/python3.10/dist-packages/IPython/core/interactiveshell.py\", line 2975, in run_cell\n\n  File \"/usr/local/lib/python3.10/dist-packages/IPython/core/interactiveshell.py\", line 3030, in _run_cell\n\n  File \"/usr/local/lib/python3.10/dist-packages/IPython/core/async_helpers.py\", line 78, in _pseudo_sync_runner\n\n  File \"/usr/local/lib/python3.10/dist-packages/IPython/core/interactiveshell.py\", line 3257, in run_cell_async\n\n  File \"/usr/local/lib/python3.10/dist-packages/IPython/core/interactiveshell.py\", line 3473, in run_ast_nodes\n\n  File \"/usr/local/lib/python3.10/dist-packages/IPython/core/interactiveshell.py\", line 3553, in run_code\n\n  File \"<ipython-input-21-7d1a7289e7ff>\", line 2, in <cell line: 2>\n\n  File \"/usr/local/lib/python3.10/dist-packages/keras/src/utils/traceback_utils.py\", line 65, in error_handler\n\n  File \"/usr/local/lib/python3.10/dist-packages/keras/src/engine/training.py\", line 1807, in fit\n\n  File \"/usr/local/lib/python3.10/dist-packages/keras/src/engine/training.py\", line 1401, in train_function\n\n  File \"/usr/local/lib/python3.10/dist-packages/keras/src/engine/training.py\", line 1384, in step_function\n\n  File \"/usr/local/lib/python3.10/dist-packages/keras/src/engine/training.py\", line 1373, in run_step\n\n  File \"/usr/local/lib/python3.10/dist-packages/keras/src/engine/training.py\", line 1151, in train_step\n\n  File \"/usr/local/lib/python3.10/dist-packages/keras/src/engine/training.py\", line 1209, in compute_loss\n\n  File \"/usr/local/lib/python3.10/dist-packages/keras/src/engine/compile_utils.py\", line 277, in __call__\n\n  File \"/usr/local/lib/python3.10/dist-packages/keras/src/losses.py\", line 143, in __call__\n\n  File \"/usr/local/lib/python3.10/dist-packages/keras/src/losses.py\", line 270, in call\n\n  File \"/usr/local/lib/python3.10/dist-packages/keras/src/losses.py\", line 2221, in categorical_crossentropy\n\n  File \"/usr/local/lib/python3.10/dist-packages/keras/src/backend.py\", line 5579, in categorical_crossentropy\n\nlogits and labels must be broadcastable: logits_size=[32,10] labels_size=[32,11]\n\t [[{{node categorical_crossentropy/softmax_cross_entropy_with_logits}}]] [Op:__inference_train_function_3999]"
          ]
        }
      ]
    },
    {
      "cell_type": "code",
      "source": [
        "# Evaluate the model\n",
        "test_loss, test_acc = model.evaluate(validation_generator, verbose=2)\n",
        "print('Test accuracy:', test_acc)"
      ],
      "metadata": {
        "id": "X11fX41PH7GS",
        "colab": {
          "base_uri": "https://localhost:8080/",
          "height": 1000
        },
        "outputId": "bcd4435b-d6d1-43f9-83a6-bc051bbee9e2"
      },
      "execution_count": 29,
      "outputs": [
        {
          "output_type": "error",
          "ename": "InvalidArgumentError",
          "evalue": "Graph execution error:\n\nDetected at node categorical_crossentropy/softmax_cross_entropy_with_logits defined at (most recent call last):\n  File \"/usr/lib/python3.10/runpy.py\", line 196, in _run_module_as_main\n\n  File \"/usr/lib/python3.10/runpy.py\", line 86, in _run_code\n\n  File \"/usr/local/lib/python3.10/dist-packages/colab_kernel_launcher.py\", line 37, in <module>\n\n  File \"/usr/local/lib/python3.10/dist-packages/traitlets/config/application.py\", line 992, in launch_instance\n\n  File \"/usr/local/lib/python3.10/dist-packages/ipykernel/kernelapp.py\", line 619, in start\n\n  File \"/usr/local/lib/python3.10/dist-packages/tornado/platform/asyncio.py\", line 195, in start\n\n  File \"/usr/lib/python3.10/asyncio/base_events.py\", line 603, in run_forever\n\n  File \"/usr/lib/python3.10/asyncio/base_events.py\", line 1909, in _run_once\n\n  File \"/usr/lib/python3.10/asyncio/events.py\", line 80, in _run\n\n  File \"/usr/local/lib/python3.10/dist-packages/tornado/ioloop.py\", line 685, in <lambda>\n\n  File \"/usr/local/lib/python3.10/dist-packages/tornado/ioloop.py\", line 738, in _run_callback\n\n  File \"/usr/local/lib/python3.10/dist-packages/tornado/gen.py\", line 825, in inner\n\n  File \"/usr/local/lib/python3.10/dist-packages/tornado/gen.py\", line 786, in run\n\n  File \"/usr/local/lib/python3.10/dist-packages/ipykernel/kernelbase.py\", line 361, in process_one\n\n  File \"/usr/local/lib/python3.10/dist-packages/tornado/gen.py\", line 234, in wrapper\n\n  File \"/usr/local/lib/python3.10/dist-packages/ipykernel/kernelbase.py\", line 261, in dispatch_shell\n\n  File \"/usr/local/lib/python3.10/dist-packages/tornado/gen.py\", line 234, in wrapper\n\n  File \"/usr/local/lib/python3.10/dist-packages/ipykernel/kernelbase.py\", line 539, in execute_request\n\n  File \"/usr/local/lib/python3.10/dist-packages/tornado/gen.py\", line 234, in wrapper\n\n  File \"/usr/local/lib/python3.10/dist-packages/ipykernel/ipkernel.py\", line 302, in do_execute\n\n  File \"/usr/local/lib/python3.10/dist-packages/ipykernel/zmqshell.py\", line 539, in run_cell\n\n  File \"/usr/local/lib/python3.10/dist-packages/IPython/core/interactiveshell.py\", line 2975, in run_cell\n\n  File \"/usr/local/lib/python3.10/dist-packages/IPython/core/interactiveshell.py\", line 3030, in _run_cell\n\n  File \"/usr/local/lib/python3.10/dist-packages/IPython/core/async_helpers.py\", line 78, in _pseudo_sync_runner\n\n  File \"/usr/local/lib/python3.10/dist-packages/IPython/core/interactiveshell.py\", line 3257, in run_cell_async\n\n  File \"/usr/local/lib/python3.10/dist-packages/IPython/core/interactiveshell.py\", line 3473, in run_ast_nodes\n\n  File \"/usr/local/lib/python3.10/dist-packages/IPython/core/interactiveshell.py\", line 3553, in run_code\n\n  File \"<ipython-input-29-c8785dc9f9f5>\", line 2, in <cell line: 2>\n\n  File \"/usr/local/lib/python3.10/dist-packages/keras/src/utils/traceback_utils.py\", line 65, in error_handler\n\n  File \"/usr/local/lib/python3.10/dist-packages/keras/src/engine/training.py\", line 2296, in evaluate\n\n  File \"/usr/local/lib/python3.10/dist-packages/keras/src/engine/training.py\", line 4108, in run_step\n\n  File \"/usr/local/lib/python3.10/dist-packages/keras/src/engine/training.py\", line 2066, in test_function\n\n  File \"/usr/local/lib/python3.10/dist-packages/keras/src/engine/training.py\", line 2049, in step_function\n\n  File \"/usr/local/lib/python3.10/dist-packages/keras/src/engine/training.py\", line 2037, in run_step\n\n  File \"/usr/local/lib/python3.10/dist-packages/keras/src/engine/training.py\", line 1919, in test_step\n\n  File \"/usr/local/lib/python3.10/dist-packages/keras/src/engine/training.py\", line 1209, in compute_loss\n\n  File \"/usr/local/lib/python3.10/dist-packages/keras/src/engine/compile_utils.py\", line 277, in __call__\n\n  File \"/usr/local/lib/python3.10/dist-packages/keras/src/losses.py\", line 143, in __call__\n\n  File \"/usr/local/lib/python3.10/dist-packages/keras/src/losses.py\", line 270, in call\n\n  File \"/usr/local/lib/python3.10/dist-packages/keras/src/losses.py\", line 2221, in categorical_crossentropy\n\n  File \"/usr/local/lib/python3.10/dist-packages/keras/src/backend.py\", line 5579, in categorical_crossentropy\n\nlogits and labels must be broadcastable: logits_size=[32,10] labels_size=[32,11]\n\t [[{{node categorical_crossentropy/softmax_cross_entropy_with_logits}}]] [Op:__inference_test_function_4373]",
          "traceback": [
            "\u001b[0;31m---------------------------------------------------------------------------\u001b[0m",
            "\u001b[0;31mInvalidArgumentError\u001b[0m                      Traceback (most recent call last)",
            "\u001b[0;32m<ipython-input-29-c8785dc9f9f5>\u001b[0m in \u001b[0;36m<cell line: 2>\u001b[0;34m()\u001b[0m\n\u001b[1;32m      1\u001b[0m \u001b[0;31m# Evaluate the model\u001b[0m\u001b[0;34m\u001b[0m\u001b[0;34m\u001b[0m\u001b[0m\n\u001b[0;32m----> 2\u001b[0;31m \u001b[0mtest_loss\u001b[0m\u001b[0;34m,\u001b[0m \u001b[0mtest_acc\u001b[0m \u001b[0;34m=\u001b[0m \u001b[0mmodel\u001b[0m\u001b[0;34m.\u001b[0m\u001b[0mevaluate\u001b[0m\u001b[0;34m(\u001b[0m\u001b[0mvalidation_generator\u001b[0m\u001b[0;34m,\u001b[0m \u001b[0mverbose\u001b[0m\u001b[0;34m=\u001b[0m\u001b[0;36m2\u001b[0m\u001b[0;34m)\u001b[0m\u001b[0;34m\u001b[0m\u001b[0;34m\u001b[0m\u001b[0m\n\u001b[0m\u001b[1;32m      3\u001b[0m \u001b[0mprint\u001b[0m\u001b[0;34m(\u001b[0m\u001b[0;34m'Test accuracy:'\u001b[0m\u001b[0;34m,\u001b[0m \u001b[0mtest_acc\u001b[0m\u001b[0;34m)\u001b[0m\u001b[0;34m\u001b[0m\u001b[0;34m\u001b[0m\u001b[0m\n",
            "\u001b[0;32m/usr/local/lib/python3.10/dist-packages/keras/src/utils/traceback_utils.py\u001b[0m in \u001b[0;36merror_handler\u001b[0;34m(*args, **kwargs)\u001b[0m\n\u001b[1;32m     68\u001b[0m             \u001b[0;31m# To get the full stack trace, call:\u001b[0m\u001b[0;34m\u001b[0m\u001b[0;34m\u001b[0m\u001b[0m\n\u001b[1;32m     69\u001b[0m             \u001b[0;31m# `tf.debugging.disable_traceback_filtering()`\u001b[0m\u001b[0;34m\u001b[0m\u001b[0;34m\u001b[0m\u001b[0m\n\u001b[0;32m---> 70\u001b[0;31m             \u001b[0;32mraise\u001b[0m \u001b[0me\u001b[0m\u001b[0;34m.\u001b[0m\u001b[0mwith_traceback\u001b[0m\u001b[0;34m(\u001b[0m\u001b[0mfiltered_tb\u001b[0m\u001b[0;34m)\u001b[0m \u001b[0;32mfrom\u001b[0m \u001b[0;32mNone\u001b[0m\u001b[0;34m\u001b[0m\u001b[0;34m\u001b[0m\u001b[0m\n\u001b[0m\u001b[1;32m     71\u001b[0m         \u001b[0;32mfinally\u001b[0m\u001b[0;34m:\u001b[0m\u001b[0;34m\u001b[0m\u001b[0;34m\u001b[0m\u001b[0m\n\u001b[1;32m     72\u001b[0m             \u001b[0;32mdel\u001b[0m \u001b[0mfiltered_tb\u001b[0m\u001b[0;34m\u001b[0m\u001b[0;34m\u001b[0m\u001b[0m\n",
            "\u001b[0;32m/usr/local/lib/python3.10/dist-packages/tensorflow/python/eager/execute.py\u001b[0m in \u001b[0;36mquick_execute\u001b[0;34m(op_name, num_outputs, inputs, attrs, ctx, name)\u001b[0m\n\u001b[1;32m     51\u001b[0m   \u001b[0;32mtry\u001b[0m\u001b[0;34m:\u001b[0m\u001b[0;34m\u001b[0m\u001b[0;34m\u001b[0m\u001b[0m\n\u001b[1;32m     52\u001b[0m     \u001b[0mctx\u001b[0m\u001b[0;34m.\u001b[0m\u001b[0mensure_initialized\u001b[0m\u001b[0;34m(\u001b[0m\u001b[0;34m)\u001b[0m\u001b[0;34m\u001b[0m\u001b[0;34m\u001b[0m\u001b[0m\n\u001b[0;32m---> 53\u001b[0;31m     tensors = pywrap_tfe.TFE_Py_Execute(ctx._handle, device_name, op_name,\n\u001b[0m\u001b[1;32m     54\u001b[0m                                         inputs, attrs, num_outputs)\n\u001b[1;32m     55\u001b[0m   \u001b[0;32mexcept\u001b[0m \u001b[0mcore\u001b[0m\u001b[0;34m.\u001b[0m\u001b[0m_NotOkStatusException\u001b[0m \u001b[0;32mas\u001b[0m \u001b[0me\u001b[0m\u001b[0;34m:\u001b[0m\u001b[0;34m\u001b[0m\u001b[0;34m\u001b[0m\u001b[0m\n",
            "\u001b[0;31mInvalidArgumentError\u001b[0m: Graph execution error:\n\nDetected at node categorical_crossentropy/softmax_cross_entropy_with_logits defined at (most recent call last):\n  File \"/usr/lib/python3.10/runpy.py\", line 196, in _run_module_as_main\n\n  File \"/usr/lib/python3.10/runpy.py\", line 86, in _run_code\n\n  File \"/usr/local/lib/python3.10/dist-packages/colab_kernel_launcher.py\", line 37, in <module>\n\n  File \"/usr/local/lib/python3.10/dist-packages/traitlets/config/application.py\", line 992, in launch_instance\n\n  File \"/usr/local/lib/python3.10/dist-packages/ipykernel/kernelapp.py\", line 619, in start\n\n  File \"/usr/local/lib/python3.10/dist-packages/tornado/platform/asyncio.py\", line 195, in start\n\n  File \"/usr/lib/python3.10/asyncio/base_events.py\", line 603, in run_forever\n\n  File \"/usr/lib/python3.10/asyncio/base_events.py\", line 1909, in _run_once\n\n  File \"/usr/lib/python3.10/asyncio/events.py\", line 80, in _run\n\n  File \"/usr/local/lib/python3.10/dist-packages/tornado/ioloop.py\", line 685, in <lambda>\n\n  File \"/usr/local/lib/python3.10/dist-packages/tornado/ioloop.py\", line 738, in _run_callback\n\n  File \"/usr/local/lib/python3.10/dist-packages/tornado/gen.py\", line 825, in inner\n\n  File \"/usr/local/lib/python3.10/dist-packages/tornado/gen.py\", line 786, in run\n\n  File \"/usr/local/lib/python3.10/dist-packages/ipykernel/kernelbase.py\", line 361, in process_one\n\n  File \"/usr/local/lib/python3.10/dist-packages/tornado/gen.py\", line 234, in wrapper\n\n  File \"/usr/local/lib/python3.10/dist-packages/ipykernel/kernelbase.py\", line 261, in dispatch_shell\n\n  File \"/usr/local/lib/python3.10/dist-packages/tornado/gen.py\", line 234, in wrapper\n\n  File \"/usr/local/lib/python3.10/dist-packages/ipykernel/kernelbase.py\", line 539, in execute_request\n\n  File \"/usr/local/lib/python3.10/dist-packages/tornado/gen.py\", line 234, in wrapper\n\n  File \"/usr/local/lib/python3.10/dist-packages/ipykernel/ipkernel.py\", line 302, in do_execute\n\n  File \"/usr/local/lib/python3.10/dist-packages/ipykernel/zmqshell.py\", line 539, in run_cell\n\n  File \"/usr/local/lib/python3.10/dist-packages/IPython/core/interactiveshell.py\", line 2975, in run_cell\n\n  File \"/usr/local/lib/python3.10/dist-packages/IPython/core/interactiveshell.py\", line 3030, in _run_cell\n\n  File \"/usr/local/lib/python3.10/dist-packages/IPython/core/async_helpers.py\", line 78, in _pseudo_sync_runner\n\n  File \"/usr/local/lib/python3.10/dist-packages/IPython/core/interactiveshell.py\", line 3257, in run_cell_async\n\n  File \"/usr/local/lib/python3.10/dist-packages/IPython/core/interactiveshell.py\", line 3473, in run_ast_nodes\n\n  File \"/usr/local/lib/python3.10/dist-packages/IPython/core/interactiveshell.py\", line 3553, in run_code\n\n  File \"<ipython-input-29-c8785dc9f9f5>\", line 2, in <cell line: 2>\n\n  File \"/usr/local/lib/python3.10/dist-packages/keras/src/utils/traceback_utils.py\", line 65, in error_handler\n\n  File \"/usr/local/lib/python3.10/dist-packages/keras/src/engine/training.py\", line 2296, in evaluate\n\n  File \"/usr/local/lib/python3.10/dist-packages/keras/src/engine/training.py\", line 4108, in run_step\n\n  File \"/usr/local/lib/python3.10/dist-packages/keras/src/engine/training.py\", line 2066, in test_function\n\n  File \"/usr/local/lib/python3.10/dist-packages/keras/src/engine/training.py\", line 2049, in step_function\n\n  File \"/usr/local/lib/python3.10/dist-packages/keras/src/engine/training.py\", line 2037, in run_step\n\n  File \"/usr/local/lib/python3.10/dist-packages/keras/src/engine/training.py\", line 1919, in test_step\n\n  File \"/usr/local/lib/python3.10/dist-packages/keras/src/engine/training.py\", line 1209, in compute_loss\n\n  File \"/usr/local/lib/python3.10/dist-packages/keras/src/engine/compile_utils.py\", line 277, in __call__\n\n  File \"/usr/local/lib/python3.10/dist-packages/keras/src/losses.py\", line 143, in __call__\n\n  File \"/usr/local/lib/python3.10/dist-packages/keras/src/losses.py\", line 270, in call\n\n  File \"/usr/local/lib/python3.10/dist-packages/keras/src/losses.py\", line 2221, in categorical_crossentropy\n\n  File \"/usr/local/lib/python3.10/dist-packages/keras/src/backend.py\", line 5579, in categorical_crossentropy\n\nlogits and labels must be broadcastable: logits_size=[32,10] labels_size=[32,11]\n\t [[{{node categorical_crossentropy/softmax_cross_entropy_with_logits}}]] [Op:__inference_test_function_4373]"
          ]
        }
      ]
    },
    {
      "cell_type": "code",
      "source": [
        "# Plot training & validation accuracy values\n",
        "import matplotlib.pyplot as plt\n",
        "\n",
        "plt.plot(history.history['accuracy'])\n",
        "plt.plot(history.history['val_accuracy'])\n",
        "plt.title('Model accuracy')\n",
        "plt.ylabel('Accuracy')\n",
        "plt.xlabel('Epoch')\n",
        "plt.legend(['Train', 'Validation'], loc='upper left')\n",
        "plt.show()"
      ],
      "metadata": {
        "id": "GzVrZYViH8b5",
        "colab": {
          "base_uri": "https://localhost:8080/",
          "height": 211
        },
        "outputId": "9f579bd3-0190-46cc-b847-116dc5990d05"
      },
      "execution_count": 30,
      "outputs": [
        {
          "output_type": "error",
          "ename": "NameError",
          "evalue": "name 'history' is not defined",
          "traceback": [
            "\u001b[0;31m---------------------------------------------------------------------------\u001b[0m",
            "\u001b[0;31mNameError\u001b[0m                                 Traceback (most recent call last)",
            "\u001b[0;32m<ipython-input-30-2043fb9b9422>\u001b[0m in \u001b[0;36m<cell line: 4>\u001b[0;34m()\u001b[0m\n\u001b[1;32m      2\u001b[0m \u001b[0;32mimport\u001b[0m \u001b[0mmatplotlib\u001b[0m\u001b[0;34m.\u001b[0m\u001b[0mpyplot\u001b[0m \u001b[0;32mas\u001b[0m \u001b[0mplt\u001b[0m\u001b[0;34m\u001b[0m\u001b[0;34m\u001b[0m\u001b[0m\n\u001b[1;32m      3\u001b[0m \u001b[0;34m\u001b[0m\u001b[0m\n\u001b[0;32m----> 4\u001b[0;31m \u001b[0mplt\u001b[0m\u001b[0;34m.\u001b[0m\u001b[0mplot\u001b[0m\u001b[0;34m(\u001b[0m\u001b[0mhistory\u001b[0m\u001b[0;34m.\u001b[0m\u001b[0mhistory\u001b[0m\u001b[0;34m[\u001b[0m\u001b[0;34m'accuracy'\u001b[0m\u001b[0;34m]\u001b[0m\u001b[0;34m)\u001b[0m\u001b[0;34m\u001b[0m\u001b[0;34m\u001b[0m\u001b[0m\n\u001b[0m\u001b[1;32m      5\u001b[0m \u001b[0mplt\u001b[0m\u001b[0;34m.\u001b[0m\u001b[0mplot\u001b[0m\u001b[0;34m(\u001b[0m\u001b[0mhistory\u001b[0m\u001b[0;34m.\u001b[0m\u001b[0mhistory\u001b[0m\u001b[0;34m[\u001b[0m\u001b[0;34m'val_accuracy'\u001b[0m\u001b[0;34m]\u001b[0m\u001b[0;34m)\u001b[0m\u001b[0;34m\u001b[0m\u001b[0;34m\u001b[0m\u001b[0m\n\u001b[1;32m      6\u001b[0m \u001b[0mplt\u001b[0m\u001b[0;34m.\u001b[0m\u001b[0mtitle\u001b[0m\u001b[0;34m(\u001b[0m\u001b[0;34m'Model accuracy'\u001b[0m\u001b[0;34m)\u001b[0m\u001b[0;34m\u001b[0m\u001b[0;34m\u001b[0m\u001b[0m\n",
            "\u001b[0;31mNameError\u001b[0m: name 'history' is not defined"
          ]
        }
      ]
    },
    {
      "cell_type": "code",
      "source": [
        "# สร้าง confusion matrix\n",
        "cm = confusion_matrix(y_test, y_pred)\n",
        "\n",
        "# แสดง confusion matrix ด้วย heatmap\n",
        "plt.figure(figsize=(8, 6))\n",
        "#sns.heatmap(cm, annot=True, fmt='d', cmap='Blues', xticklabels=['Predicted Negative', 'Predicted Positive'], yticklabels=['Actual Negative', 'Actual Positive'])\n",
        "sns.heatmap(cm, annot=True, fmt='d', cmap='Blues', xticklabels=[''], yticklabels=[''])\n",
        "plt.xlabel('Predicted Label')\n",
        "plt.ylabel('True Label')\n",
        "plt.title('Confusion Matrix')\n",
        "plt.show()"
      ],
      "metadata": {
        "id": "57Cw4gkLfao8"
      },
      "execution_count": null,
      "outputs": []
    },
    {
      "cell_type": "markdown",
      "source": [
        "อธิบายเเละวิเคราะห์ผลการประเมินประสิทธิภาพของKNNเเละCNN\n",
        "-CNN มักมีประสิทธิภาพที่ดีในการจัดการกับข้อมูลที่มีโครงสร้างซับซ้อน\n",
        "-KNN มักจะให้ประสิทธิภาพที่ดีในข้อมูลที่มีลักษณะเหมือนกัน หรือมีโครงสร้างคล้ายกัน เช่นการทำนายภาพของอากาศในพื้นที่ที่มีลักษณะอากาศเดียวกัน แต่อาจมีประสิทธิภาพที่ต่ำในข้อมูลที่มีการแยกแยะลักษณะอย่างชัดเจน"
      ],
      "metadata": {
        "id": "ZB3IMHbngUrs"
      }
    }
  ]
}